running test
running egg_info
writing requirements to ably_python.egg-info/requires.txt
writing ably_python.egg-info/PKG-INFO
writing top-level names to ably_python.egg-info/top_level.txt
writing dependency_links to ably_python.egg-info/dependency_links.txt
reading manifest file 'ably_python.egg-info/SOURCES.txt'
writing manifest file 'ably_python.egg-info/SOURCES.txt'
running build_ext
test_app_stats_01_minute_level_forwards (test.ably.restappstats_test.TestRestAppStats) ... FAIL
test_app_stats_02_hour_level_forwards (test.ably.restappstats_test.TestRestAppStats) ... FAIL
test_app_stats_03_day_level_forwards (test.ably.restappstats_test.TestRestAppStats) ... ok
test_app_stats_04_month_level_forwards (test.ably.restappstats_test.TestRestAppStats) ... ok
test_app_stats_05_minute_level_backwards (test.ably.restappstats_test.TestRestAppStats) ... FAIL
test_app_stats_06_hour_level_backwards (test.ably.restappstats_test.TestRestAppStats) ... FAIL
test_app_stats_07_day_level_backwards (test.ably.restappstats_test.TestRestAppStats) ... ok
test_app_stats_08_month_level_backwards (test.ably.restappstats_test.TestRestAppStats) ... ok
test_app_stats_09_limit_backwards (test.ably.restappstats_test.TestRestAppStats) ... FAIL
test_app_stats_10_limit_forwards (test.ably.restappstats_test.TestRestAppStats) ... FAIL
test_app_stats_11_pagination_backwards (test.ably.restappstats_test.TestRestAppStats) ... FAIL
test_app_stats_12_pagination_forwards (test.ably.restappstats_test.TestRestAppStats) ... FAIL
test_app_stats_13_pagination_backwards_get_first (test.ably.restappstats_test.TestRestAppStats) ... FAIL
test_app_stats_14_pagination_forwards_get_first (test.ably.restappstats_test.TestRestAppStats) ... FAIL
test_auth_init_key_only (test.ably.restauth_test.TestAuth) ... ok
test_auth_init_token_only (test.ably.restauth_test.TestAuth) ... ok
test_auth_init_with_key_and_client_id (test.ably.restauth_test.TestAuth) ... ok
test_auth_init_with_token (test.ably.restauth_test.TestAuth) ... ok
test_auth_init_with_token_callback (test.ably.restauth_test.TestAuth) ... ok
test_blanket_intersection_with_key (test.ably.restcapability_test.TestRestCapability) ... ok
test_empty_ops_intersection (test.ably.restcapability_test.TestRestCapability) ... ok
test_empty_paths_intersection (test.ably.restcapability_test.TestRestCapability) ... ok
test_equal_intersection_with_key (test.ably.restcapability_test.TestRestCapability) ... ok
test_invalid_capabilities (test.ably.restcapability_test.TestRestCapability) ... ok
test_invalid_capabilities_2 (test.ably.restcapability_test.TestRestCapability) ... ok
test_invalid_capabilities_3 (test.ably.restcapability_test.TestRestCapability) ... ok
test_non_empty_ops_intersection (test.ably.restcapability_test.TestRestCapability) ... ok
test_non_empty_paths_intersection (test.ably.restcapability_test.TestRestCapability) ... ok
test_wildcard_ops_intersection (test.ably.restcapability_test.TestRestCapability) ... ok
test_wildcard_ops_intersection_2 (test.ably.restcapability_test.TestRestCapability) ... ok
test_wildcard_resources_intersection (test.ably.restcapability_test.TestRestCapability) ... ok
test_wildcard_resources_intersection_2 (test.ably.restcapability_test.TestRestCapability) ... ok
test_wildcard_resources_intersection_3 (test.ably.restcapability_test.TestRestCapability) ... ok
test_channel_history_limit_backwards (test.ably.restchannelhistory_test.TestRestChannelHistory) ... ok
test_channel_history_limit_forwards (test.ably.restchannelhistory_test.TestRestChannelHistory) ... ok
test_channel_history_multi_50_backwards (test.ably.restchannelhistory_test.TestRestChannelHistory) ... ok
test_channel_history_multi_50_forwards (test.ably.restchannelhistory_test.TestRestChannelHistory) ... ok
test_channel_history_paginate_backwards (test.ably.restchannelhistory_test.TestRestChannelHistory) ... ERROR
test_channel_history_paginate_backwards_rel_first (test.ably.restchannelhistory_test.TestRestChannelHistory) ... ERROR
test_channel_history_paginate_forwards (test.ably.restchannelhistory_test.TestRestChannelHistory) ... ERROR
test_channel_history_time_backwards (test.ably.restchannelhistory_test.TestRestChannelHistory) ... ERROR
test_channel_history_time_forwards (test.ably.restchannelhistory_test.TestRestChannelHistory) ... ERROR
test_channel_history_types (test.ably.restchannelhistory_test.TestRestChannelHistory) ... ERROR
test_publish_various_datatypes_text (test.ably.restchannelpublish_test.TestRestChannelPublish) ... ERROR
test_cbc_channel_cipher (test.ably.restcrypto_test.TestRestCrypto) ... ok
test_crypto_publish_key_mismatch (test.ably.restcrypto_test.TestRestCrypto) ... ERROR
test_crypto_publish_text (test.ably.restcrypto_test.TestRestCrypto) ... ERROR
test_crypto_publish_text_256 (test.ably.restcrypto_test.TestRestCrypto) ... ERROR
test_crypto_send_encrypted_unhandled (test.ably.restcrypto_test.TestRestCrypto) ... ERROR
test_crypto_send_unencrypted (test.ably.restcrypto_test.TestRestCrypto) ... ERROR
test_key_in_options (test.ably.restinit_test.TestRestInit) ... ok
test_key_only (test.ably.restinit_test.TestRestInit) ... ok
test_specified_host (test.ably.restinit_test.TestRestInit) ... ok
test_specified_port (test.ably.restinit_test.TestRestInit) ... ok
test_tls_can_be_disabled (test.ably.restinit_test.TestRestInit) ... ok
test_tls_defaults_to_true (test.ably.restinit_test.TestRestInit) ... ok
test_time_accuracy (test.ably.resttime_test.TestRestTime) ... ERROR
test_time_fails_without_valid_host (test.ably.resttime_test.TestRestTime) ... ok
test_time_without_key_or_token (test.ably.resttime_test.TestRestTime) ... ERROR
test_request_token_explicit_invalid_timestamp (test.ably.resttoken_test.TestRestToken) ... ERROR
test_request_token_explicit_timestamp (test.ably.resttoken_test.TestRestToken) ... ERROR
test_request_token_null_params (test.ably.resttoken_test.TestRestToken) ... ERROR
test_request_token_with_capability_that_subsets_key_capability (test.ably.resttoken_test.TestRestToken) ... ERROR
test_request_token_with_duplicate_nonce (test.ably.resttoken_test.TestRestToken) ... ERROR
test_request_token_with_invalid_mac (test.ably.resttoken_test.TestRestToken) ... ok
test_request_token_with_specified_key (test.ably.resttoken_test.TestRestToken) ... ERROR
test_request_token_with_specified_ttl (test.ably.resttoken_test.TestRestToken) ... ERROR
test_request_token_with_system_timestamp (test.ably.resttoken_test.TestRestToken) ... ERROR
test_token_generation_with_invalid_ttl (test.ably.resttoken_test.TestRestToken) ... ok
test_token_with_excessive_ttl (test.ably.resttoken_test.TestRestToken) ... ok
ERROR

======================================================================
ERROR: test_channel_history_paginate_backwards (test.ably.restchannelhistory_test.TestRestChannelHistory)
----------------------------------------------------------------------
Traceback (most recent call last):
  File "/home/main/tmp/ably-python-rest/test/ably/restchannelhistory_test.py", line 283, in test_channel_history_paginate_backwards
    history = history0.history(direction='backwards', limit=10)
  File "/home/main/tmp/ably-python-rest/ably/util/exceptions.py", line 61, in wrapper
    return func(*args, **kwargs)
  File "/home/main/tmp/ably-python-rest/ably/rest/channel.py", line 93, in history
    return PaginatedResult.paginated_query(self.ably.http, path, None, message_handler)
  File "/home/main/tmp/ably-python-rest/ably/http/paginatedresult.py", line 52, in paginated_query
    return PaginatedResult.paginated_query_with_request(http, req, response_processor)
  File "/home/main/tmp/ably-python-rest/ably/http/paginatedresult.py", line 56, in paginated_query_with_request
    response = http.request(request)
  File "/home/main/tmp/ably-python-rest/ably/http/http.py", line 165, in request
    return self.make_request(request.method, request.url, headers=request.headers, body=request.body)
  File "/home/main/tmp/ably-python-rest/ably/http/http.py", line 22, in wrapper
    return func(http, *args, **kwargs)
  File "/home/main/tmp/ably-python-rest/ably/http/http.py", line 51, in wrapper
    return func(rest, *args, **kwargs)
  File "/home/main/tmp/ably-python-rest/ably/http/http.py", line 160, in make_request
    AblyException.raise_for_response(response)
  File "/home/main/tmp/ably-python-rest/ably/util/exceptions.py", line 46, in raise_for_response
    response.status_code * 100)
AblyException: 
-------------------- >> begin captured logging << --------------------
ably.util.exceptions: DEBUG: Response: 503 
--------------------- >> end captured logging << ---------------------

======================================================================
ERROR: test_channel_history_paginate_backwards_rel_first (test.ably.restchannelhistory_test.TestRestChannelHistory)
----------------------------------------------------------------------
Traceback (most recent call last):
  File "/home/main/tmp/ably-python-rest/test/ably/restchannelhistory_test.py", line 361, in test_channel_history_paginate_backwards_rel_first
    history0.publish('history%d' % i, i)
  File "/home/main/tmp/ably-python-rest/ably/util/exceptions.py", line 61, in wrapper
    return func(*args, **kwargs)
  File "/home/main/tmp/ably-python-rest/ably/rest/channel.py", line 116, in publish
    return self.ably.http.post(path, headers=headers, body=request_body, timeout=timeout).json()
  File "/home/main/tmp/ably-python-rest/ably/http/http.py", line 171, in post
    return self.make_request('POST', url, headers=headers, body=body, skip_auth=skip_auth, timeout=timeout)
  File "/home/main/tmp/ably-python-rest/ably/http/http.py", line 22, in wrapper
    return func(http, *args, **kwargs)
  File "/home/main/tmp/ably-python-rest/ably/http/http.py", line 51, in wrapper
    return func(rest, *args, **kwargs)
  File "/home/main/tmp/ably-python-rest/ably/http/http.py", line 160, in make_request
    AblyException.raise_for_response(response)
  File "/home/main/tmp/ably-python-rest/ably/util/exceptions.py", line 46, in raise_for_response
    response.status_code * 100)
AblyException: 
-------------------- >> begin captured logging << --------------------
ably.util.exceptions: DEBUG: Response: 503 
--------------------- >> end captured logging << ---------------------

======================================================================
ERROR: test_channel_history_paginate_forwards (test.ably.restchannelhistory_test.TestRestChannelHistory)
----------------------------------------------------------------------
Traceback (most recent call last):
  File "/home/main/tmp/ably-python-rest/test/ably/restchannelhistory_test.py", line 320, in test_channel_history_paginate_forwards
    history0.publish('history%d' % i, i)
  File "/home/main/tmp/ably-python-rest/ably/util/exceptions.py", line 61, in wrapper
    return func(*args, **kwargs)
  File "/home/main/tmp/ably-python-rest/ably/rest/channel.py", line 116, in publish
    return self.ably.http.post(path, headers=headers, body=request_body, timeout=timeout).json()
  File "/home/main/tmp/ably-python-rest/ably/http/http.py", line 171, in post
    return self.make_request('POST', url, headers=headers, body=body, skip_auth=skip_auth, timeout=timeout)
  File "/home/main/tmp/ably-python-rest/ably/http/http.py", line 22, in wrapper
    return func(http, *args, **kwargs)
  File "/home/main/tmp/ably-python-rest/ably/http/http.py", line 51, in wrapper
    return func(rest, *args, **kwargs)
  File "/home/main/tmp/ably-python-rest/ably/http/http.py", line 160, in make_request
    AblyException.raise_for_response(response)
  File "/home/main/tmp/ably-python-rest/ably/util/exceptions.py", line 46, in raise_for_response
    response.status_code * 100)
AblyException: 
-------------------- >> begin captured logging << --------------------
ably.util.exceptions: DEBUG: Response: 503 
--------------------- >> end captured logging << ---------------------

======================================================================
ERROR: test_channel_history_time_backwards (test.ably.restchannelhistory_test.TestRestChannelHistory)
----------------------------------------------------------------------
Traceback (most recent call last):
  File "/home/main/tmp/ably-python-rest/test/ably/restchannelhistory_test.py", line 205, in test_channel_history_time_backwards
    history0.publish('history%d' % i, i)
  File "/home/main/tmp/ably-python-rest/ably/util/exceptions.py", line 61, in wrapper
    return func(*args, **kwargs)
  File "/home/main/tmp/ably-python-rest/ably/rest/channel.py", line 116, in publish
    return self.ably.http.post(path, headers=headers, body=request_body, timeout=timeout).json()
  File "/home/main/tmp/ably-python-rest/ably/http/http.py", line 171, in post
    return self.make_request('POST', url, headers=headers, body=body, skip_auth=skip_auth, timeout=timeout)
  File "/home/main/tmp/ably-python-rest/ably/http/http.py", line 22, in wrapper
    return func(http, *args, **kwargs)
  File "/home/main/tmp/ably-python-rest/ably/http/http.py", line 51, in wrapper
    return func(rest, *args, **kwargs)
  File "/home/main/tmp/ably-python-rest/ably/http/http.py", line 160, in make_request
    AblyException.raise_for_response(response)
  File "/home/main/tmp/ably-python-rest/ably/util/exceptions.py", line 46, in raise_for_response
    response.status_code * 100)
AblyException: 
-------------------- >> begin captured logging << --------------------
ably.util.exceptions: DEBUG: Response: 503 
--------------------- >> end captured logging << ---------------------

======================================================================
ERROR: test_channel_history_time_forwards (test.ably.restchannelhistory_test.TestRestChannelHistory)
----------------------------------------------------------------------
Traceback (most recent call last):
  File "/home/main/tmp/ably-python-rest/test/ably/restchannelhistory_test.py", line 172, in test_channel_history_time_forwards
    history0.publish('history%d' % i, i)
  File "/home/main/tmp/ably-python-rest/ably/util/exceptions.py", line 61, in wrapper
    return func(*args, **kwargs)
  File "/home/main/tmp/ably-python-rest/ably/rest/channel.py", line 116, in publish
    return self.ably.http.post(path, headers=headers, body=request_body, timeout=timeout).json()
  File "/home/main/tmp/ably-python-rest/ably/http/http.py", line 171, in post
    return self.make_request('POST', url, headers=headers, body=body, skip_auth=skip_auth, timeout=timeout)
  File "/home/main/tmp/ably-python-rest/ably/http/http.py", line 22, in wrapper
    return func(http, *args, **kwargs)
  File "/home/main/tmp/ably-python-rest/ably/http/http.py", line 51, in wrapper
    return func(rest, *args, **kwargs)
  File "/home/main/tmp/ably-python-rest/ably/http/http.py", line 160, in make_request
    AblyException.raise_for_response(response)
  File "/home/main/tmp/ably-python-rest/ably/util/exceptions.py", line 46, in raise_for_response
    response.status_code * 100)
AblyException: 
-------------------- >> begin captured logging << --------------------
ably.util.exceptions: DEBUG: Response: 503 
--------------------- >> end captured logging << ---------------------

======================================================================
ERROR: test_channel_history_types (test.ably.restchannelhistory_test.TestRestChannelHistory)
----------------------------------------------------------------------
Traceback (most recent call last):
  File "/home/main/tmp/ably-python-rest/test/ably/restchannelhistory_test.py", line 39, in test_channel_history_types
    history0.publish('history0', True)
  File "/home/main/tmp/ably-python-rest/ably/util/exceptions.py", line 61, in wrapper
    return func(*args, **kwargs)
  File "/home/main/tmp/ably-python-rest/ably/rest/channel.py", line 116, in publish
    return self.ably.http.post(path, headers=headers, body=request_body, timeout=timeout).json()
  File "/home/main/tmp/ably-python-rest/ably/http/http.py", line 171, in post
    return self.make_request('POST', url, headers=headers, body=body, skip_auth=skip_auth, timeout=timeout)
  File "/home/main/tmp/ably-python-rest/ably/http/http.py", line 22, in wrapper
    return func(http, *args, **kwargs)
  File "/home/main/tmp/ably-python-rest/ably/http/http.py", line 51, in wrapper
    return func(rest, *args, **kwargs)
  File "/home/main/tmp/ably-python-rest/ably/http/http.py", line 160, in make_request
    AblyException.raise_for_response(response)
  File "/home/main/tmp/ably-python-rest/ably/util/exceptions.py", line 46, in raise_for_response
    response.status_code * 100)
AblyException: 
-------------------- >> begin captured logging << --------------------
ably.util.exceptions: DEBUG: Response: 503 
--------------------- >> end captured logging << ---------------------

======================================================================
ERROR: test_publish_various_datatypes_text (test.ably.restchannelpublish_test.TestRestChannelPublish)
----------------------------------------------------------------------
Traceback (most recent call last):
  File "/home/main/tmp/ably-python-rest/test/ably/restchannelpublish_test.py", line 42, in test_publish_various_datatypes_text
    publish0.publish("publish0", True)
  File "/home/main/tmp/ably-python-rest/ably/util/exceptions.py", line 61, in wrapper
    return func(*args, **kwargs)
  File "/home/main/tmp/ably-python-rest/ably/rest/channel.py", line 116, in publish
    return self.ably.http.post(path, headers=headers, body=request_body, timeout=timeout).json()
  File "/home/main/tmp/ably-python-rest/ably/http/http.py", line 171, in post
    return self.make_request('POST', url, headers=headers, body=body, skip_auth=skip_auth, timeout=timeout)
  File "/home/main/tmp/ably-python-rest/ably/http/http.py", line 22, in wrapper
    return func(http, *args, **kwargs)
  File "/home/main/tmp/ably-python-rest/ably/http/http.py", line 51, in wrapper
    return func(rest, *args, **kwargs)
  File "/home/main/tmp/ably-python-rest/ably/http/http.py", line 160, in make_request
    AblyException.raise_for_response(response)
  File "/home/main/tmp/ably-python-rest/ably/util/exceptions.py", line 46, in raise_for_response
    response.status_code * 100)
AblyException: 
-------------------- >> begin captured logging << --------------------
ably.rest.auth: INFO: anonymous, using basic auth
ably.rest.auth: INFO: anonymous, using basic auth
ably.util.exceptions: DEBUG: Response: 503 
--------------------- >> end captured logging << ---------------------

======================================================================
ERROR: test_crypto_publish_key_mismatch (test.ably.restcrypto_test.TestRestCrypto)
----------------------------------------------------------------------
Traceback (most recent call last):
  File "/home/main/tmp/ably-python-rest/test/ably/restcrypto_test.py", line 151, in test_crypto_publish_key_mismatch
    publish0.publish("publish0", True)
  File "/home/main/tmp/ably-python-rest/ably/util/exceptions.py", line 61, in wrapper
    return func(*args, **kwargs)
  File "/home/main/tmp/ably-python-rest/ably/rest/channel.py", line 116, in publish
    return self.ably.http.post(path, headers=headers, body=request_body, timeout=timeout).json()
  File "/home/main/tmp/ably-python-rest/ably/http/http.py", line 171, in post
    return self.make_request('POST', url, headers=headers, body=body, skip_auth=skip_auth, timeout=timeout)
  File "/home/main/tmp/ably-python-rest/ably/http/http.py", line 22, in wrapper
    return func(http, *args, **kwargs)
  File "/home/main/tmp/ably-python-rest/ably/http/http.py", line 51, in wrapper
    return func(rest, *args, **kwargs)
  File "/home/main/tmp/ably-python-rest/ably/http/http.py", line 160, in make_request
    AblyException.raise_for_response(response)
  File "/home/main/tmp/ably-python-rest/ably/util/exceptions.py", line 46, in raise_for_response
    response.status_code * 100)
AblyException: 
-------------------- >> begin captured logging << --------------------
ably.util.exceptions: DEBUG: Response: 503 
--------------------- >> end captured logging << ---------------------

======================================================================
ERROR: test_crypto_publish_text (test.ably.restcrypto_test.TestRestCrypto)
----------------------------------------------------------------------
Traceback (most recent call last):
  File "/home/main/tmp/ably-python-rest/test/ably/restcrypto_test.py", line 65, in test_crypto_publish_text
    publish0.publish("publish0", True)
  File "/home/main/tmp/ably-python-rest/ably/util/exceptions.py", line 61, in wrapper
    return func(*args, **kwargs)
  File "/home/main/tmp/ably-python-rest/ably/rest/channel.py", line 116, in publish
    return self.ably.http.post(path, headers=headers, body=request_body, timeout=timeout).json()
  File "/home/main/tmp/ably-python-rest/ably/http/http.py", line 171, in post
    return self.make_request('POST', url, headers=headers, body=body, skip_auth=skip_auth, timeout=timeout)
  File "/home/main/tmp/ably-python-rest/ably/http/http.py", line 22, in wrapper
    return func(http, *args, **kwargs)
  File "/home/main/tmp/ably-python-rest/ably/http/http.py", line 51, in wrapper
    return func(rest, *args, **kwargs)
  File "/home/main/tmp/ably-python-rest/ably/http/http.py", line 160, in make_request
    AblyException.raise_for_response(response)
  File "/home/main/tmp/ably-python-rest/ably/util/exceptions.py", line 46, in raise_for_response
    response.status_code * 100)
AblyException: 
-------------------- >> begin captured logging << --------------------
ably.util.exceptions: DEBUG: Response: 503 
--------------------- >> end captured logging << ---------------------

======================================================================
ERROR: test_crypto_publish_text_256 (test.ably.restcrypto_test.TestRestCrypto)
----------------------------------------------------------------------
Traceback (most recent call last):
  File "/home/main/tmp/ably-python-rest/test/ably/restcrypto_test.py", line 110, in test_crypto_publish_text_256
    publish0.publish("publish0", True)
  File "/home/main/tmp/ably-python-rest/ably/util/exceptions.py", line 61, in wrapper
    return func(*args, **kwargs)
  File "/home/main/tmp/ably-python-rest/ably/rest/channel.py", line 116, in publish
    return self.ably.http.post(path, headers=headers, body=request_body, timeout=timeout).json()
  File "/home/main/tmp/ably-python-rest/ably/http/http.py", line 171, in post
    return self.make_request('POST', url, headers=headers, body=body, skip_auth=skip_auth, timeout=timeout)
  File "/home/main/tmp/ably-python-rest/ably/http/http.py", line 22, in wrapper
    return func(http, *args, **kwargs)
  File "/home/main/tmp/ably-python-rest/ably/http/http.py", line 51, in wrapper
    return func(rest, *args, **kwargs)
  File "/home/main/tmp/ably-python-rest/ably/http/http.py", line 160, in make_request
    AblyException.raise_for_response(response)
  File "/home/main/tmp/ably-python-rest/ably/util/exceptions.py", line 46, in raise_for_response
    response.status_code * 100)
AblyException: 
-------------------- >> begin captured logging << --------------------
ably.util.exceptions: DEBUG: Response: 503 
--------------------- >> end captured logging << ---------------------

======================================================================
ERROR: test_crypto_send_encrypted_unhandled (test.ably.restcrypto_test.TestRestCrypto)
----------------------------------------------------------------------
Traceback (most recent call last):
  File "/home/main/tmp/ably-python-rest/test/ably/restcrypto_test.py", line 213, in test_crypto_send_encrypted_unhandled
    publish0.publish("publish0", True)
  File "/home/main/tmp/ably-python-rest/ably/util/exceptions.py", line 61, in wrapper
    return func(*args, **kwargs)
  File "/home/main/tmp/ably-python-rest/ably/rest/channel.py", line 116, in publish
    return self.ably.http.post(path, headers=headers, body=request_body, timeout=timeout).json()
  File "/home/main/tmp/ably-python-rest/ably/http/http.py", line 171, in post
    return self.make_request('POST', url, headers=headers, body=body, skip_auth=skip_auth, timeout=timeout)
  File "/home/main/tmp/ably-python-rest/ably/http/http.py", line 22, in wrapper
    return func(http, *args, **kwargs)
  File "/home/main/tmp/ably-python-rest/ably/http/http.py", line 51, in wrapper
    return func(rest, *args, **kwargs)
  File "/home/main/tmp/ably-python-rest/ably/http/http.py", line 160, in make_request
    AblyException.raise_for_response(response)
  File "/home/main/tmp/ably-python-rest/ably/util/exceptions.py", line 46, in raise_for_response
    response.status_code * 100)
AblyException: 
-------------------- >> begin captured logging << --------------------
ably.util.exceptions: DEBUG: Response: 503 
--------------------- >> end captured logging << ---------------------

======================================================================
ERROR: test_crypto_send_unencrypted (test.ably.restcrypto_test.TestRestCrypto)
----------------------------------------------------------------------
Traceback (most recent call last):
  File "/home/main/tmp/ably-python-rest/test/ably/restcrypto_test.py", line 170, in test_crypto_send_unencrypted
    publish0.publish("publish0", True)
  File "/home/main/tmp/ably-python-rest/ably/util/exceptions.py", line 61, in wrapper
    return func(*args, **kwargs)
  File "/home/main/tmp/ably-python-rest/ably/rest/channel.py", line 116, in publish
    return self.ably.http.post(path, headers=headers, body=request_body, timeout=timeout).json()
  File "/home/main/tmp/ably-python-rest/ably/http/http.py", line 171, in post
    return self.make_request('POST', url, headers=headers, body=body, skip_auth=skip_auth, timeout=timeout)
  File "/home/main/tmp/ably-python-rest/ably/http/http.py", line 22, in wrapper
    return func(http, *args, **kwargs)
  File "/home/main/tmp/ably-python-rest/ably/http/http.py", line 51, in wrapper
    return func(rest, *args, **kwargs)
  File "/home/main/tmp/ably-python-rest/ably/http/http.py", line 160, in make_request
    AblyException.raise_for_response(response)
  File "/home/main/tmp/ably-python-rest/ably/util/exceptions.py", line 46, in raise_for_response
    response.status_code * 100)
AblyException: 
-------------------- >> begin captured logging << --------------------
ably.util.exceptions: DEBUG: Response: 503 
--------------------- >> end captured logging << ---------------------

======================================================================
ERROR: test_time_accuracy (test.ably.resttime_test.TestRestTime)
----------------------------------------------------------------------
Traceback (most recent call last):
  File "/home/main/tmp/ably-python-rest/test/ably/resttime_test.py", line 23, in test_time_accuracy
    reported_time = ably.time()
  File "/home/main/tmp/ably-python-rest/ably/util/exceptions.py", line 61, in wrapper
    return func(*args, **kwargs)
  File "/home/main/tmp/ably-python-rest/ably/rest/rest.py", line 101, in time
    r = self.http.get('/time', skip_auth=True, timeout=timeout)
  File "/home/main/tmp/ably-python-rest/ably/http/http.py", line 168, in get
    return self.make_request('GET', url, headers=headers, skip_auth=skip_auth, timeout=timeout)
  File "/home/main/tmp/ably-python-rest/ably/http/http.py", line 22, in wrapper
    return func(http, *args, **kwargs)
  File "/home/main/tmp/ably-python-rest/ably/http/http.py", line 46, in wrapper
    return func(rest, *args, **kwargs)
  File "/home/main/tmp/ably-python-rest/ably/http/http.py", line 160, in make_request
    AblyException.raise_for_response(response)
  File "/home/main/tmp/ably-python-rest/ably/util/exceptions.py", line 46, in raise_for_response
    response.status_code * 100)
AblyException: 
-------------------- >> begin captured logging << --------------------
ably.rest.auth: INFO: anonymous, using basic auth
ably.util.exceptions: DEBUG: Response: 503 
--------------------- >> end captured logging << ---------------------

======================================================================
ERROR: test_time_without_key_or_token (test.ably.resttime_test.TestRestTime)
----------------------------------------------------------------------
Traceback (most recent call last):
  File "/home/main/tmp/ably-python-rest/test/ably/resttime_test.py", line 35, in test_time_without_key_or_token
    ably.time()
  File "/home/main/tmp/ably-python-rest/ably/util/exceptions.py", line 61, in wrapper
    return func(*args, **kwargs)
  File "/home/main/tmp/ably-python-rest/ably/rest/rest.py", line 101, in time
    r = self.http.get('/time', skip_auth=True, timeout=timeout)
  File "/home/main/tmp/ably-python-rest/ably/http/http.py", line 168, in get
    return self.make_request('GET', url, headers=headers, skip_auth=skip_auth, timeout=timeout)
  File "/home/main/tmp/ably-python-rest/ably/http/http.py", line 22, in wrapper
    return func(http, *args, **kwargs)
  File "/home/main/tmp/ably-python-rest/ably/http/http.py", line 46, in wrapper
    return func(rest, *args, **kwargs)
  File "/home/main/tmp/ably-python-rest/ably/http/http.py", line 160, in make_request
    AblyException.raise_for_response(response)
  File "/home/main/tmp/ably-python-rest/ably/util/exceptions.py", line 46, in raise_for_response
    response.status_code * 100)
AblyException: 
-------------------- >> begin captured logging << --------------------
ably.rest.auth: INFO: no authentication parameters supplied
ably.util.exceptions: DEBUG: Response: 503 
--------------------- >> end captured logging << ---------------------

======================================================================
ERROR: test_request_token_explicit_invalid_timestamp (test.ably.resttoken_test.TestRestToken)
----------------------------------------------------------------------
Traceback (most recent call last):
  File "/home/main/tmp/ably-python-rest/test/ably/resttoken_test.py", line 67, in test_request_token_explicit_invalid_timestamp
    request_time = self.server_time()
  File "/home/main/tmp/ably-python-rest/test/ably/resttoken_test.py", line 23, in server_time
    return int(self.ably.time() / 1000.0)
  File "/home/main/tmp/ably-python-rest/ably/util/exceptions.py", line 61, in wrapper
    return func(*args, **kwargs)
  File "/home/main/tmp/ably-python-rest/ably/rest/rest.py", line 101, in time
    r = self.http.get('/time', skip_auth=True, timeout=timeout)
  File "/home/main/tmp/ably-python-rest/ably/http/http.py", line 168, in get
    return self.make_request('GET', url, headers=headers, skip_auth=skip_auth, timeout=timeout)
  File "/home/main/tmp/ably-python-rest/ably/http/http.py", line 22, in wrapper
    return func(http, *args, **kwargs)
  File "/home/main/tmp/ably-python-rest/ably/http/http.py", line 46, in wrapper
    return func(rest, *args, **kwargs)
  File "/home/main/tmp/ably-python-rest/ably/http/http.py", line 160, in make_request
    AblyException.raise_for_response(response)
  File "/home/main/tmp/ably-python-rest/ably/util/exceptions.py", line 46, in raise_for_response
    response.status_code * 100)
AblyException: 
-------------------- >> begin captured logging << --------------------
ably.rest.auth: INFO: anonymous, using basic auth
ably.util.exceptions: DEBUG: Response: 503 
--------------------- >> end captured logging << ---------------------

======================================================================
ERROR: test_request_token_explicit_timestamp (test.ably.resttoken_test.TestRestToken)
----------------------------------------------------------------------
Traceback (most recent call last):
  File "/home/main/tmp/ably-python-rest/test/ably/resttoken_test.py", line 50, in test_request_token_explicit_timestamp
    pre_time = self.server_time()
  File "/home/main/tmp/ably-python-rest/test/ably/resttoken_test.py", line 23, in server_time
    return int(self.ably.time() / 1000.0)
  File "/home/main/tmp/ably-python-rest/ably/util/exceptions.py", line 61, in wrapper
    return func(*args, **kwargs)
  File "/home/main/tmp/ably-python-rest/ably/rest/rest.py", line 101, in time
    r = self.http.get('/time', skip_auth=True, timeout=timeout)
  File "/home/main/tmp/ably-python-rest/ably/http/http.py", line 168, in get
    return self.make_request('GET', url, headers=headers, skip_auth=skip_auth, timeout=timeout)
  File "/home/main/tmp/ably-python-rest/ably/http/http.py", line 22, in wrapper
    return func(http, *args, **kwargs)
  File "/home/main/tmp/ably-python-rest/ably/http/http.py", line 46, in wrapper
    return func(rest, *args, **kwargs)
  File "/home/main/tmp/ably-python-rest/ably/http/http.py", line 160, in make_request
    AblyException.raise_for_response(response)
  File "/home/main/tmp/ably-python-rest/ably/util/exceptions.py", line 46, in raise_for_response
    response.status_code * 100)
AblyException: 
-------------------- >> begin captured logging << --------------------
ably.rest.auth: INFO: anonymous, using basic auth
ably.util.exceptions: DEBUG: Response: 503 
--------------------- >> end captured logging << ---------------------

======================================================================
ERROR: test_request_token_null_params (test.ably.resttoken_test.TestRestToken)
----------------------------------------------------------------------
Traceback (most recent call last):
  File "/home/main/tmp/ably-python-rest/test/ably/resttoken_test.py", line 35, in test_request_token_null_params
    pre_time = self.server_time()
  File "/home/main/tmp/ably-python-rest/test/ably/resttoken_test.py", line 23, in server_time
    return int(self.ably.time() / 1000.0)
  File "/home/main/tmp/ably-python-rest/ably/util/exceptions.py", line 61, in wrapper
    return func(*args, **kwargs)
  File "/home/main/tmp/ably-python-rest/ably/rest/rest.py", line 101, in time
    r = self.http.get('/time', skip_auth=True, timeout=timeout)
  File "/home/main/tmp/ably-python-rest/ably/http/http.py", line 168, in get
    return self.make_request('GET', url, headers=headers, skip_auth=skip_auth, timeout=timeout)
  File "/home/main/tmp/ably-python-rest/ably/http/http.py", line 22, in wrapper
    return func(http, *args, **kwargs)
  File "/home/main/tmp/ably-python-rest/ably/http/http.py", line 46, in wrapper
    return func(rest, *args, **kwargs)
  File "/home/main/tmp/ably-python-rest/ably/http/http.py", line 160, in make_request
    AblyException.raise_for_response(response)
  File "/home/main/tmp/ably-python-rest/ably/util/exceptions.py", line 46, in raise_for_response
    response.status_code * 100)
AblyException: 
-------------------- >> begin captured logging << --------------------
ably.rest.auth: INFO: anonymous, using basic auth
ably.util.exceptions: DEBUG: Response: 503 
--------------------- >> end captured logging << ---------------------

======================================================================
ERROR: test_request_token_with_capability_that_subsets_key_capability (test.ably.resttoken_test.TestRestToken)
----------------------------------------------------------------------
Traceback (most recent call last):
  File "/home/main/tmp/ably-python-rest/test/ably/resttoken_test.py", line 111, in test_request_token_with_capability_that_subsets_key_capability
    token_details = self.ably.auth.request_token(token_params=token_params)
  File "/home/main/tmp/ably-python-rest/ably/rest/auth.py", line 145, in request_token
    skip_auth=True)
  File "/home/main/tmp/ably-python-rest/ably/http/http.py", line 171, in post
    return self.make_request('POST', url, headers=headers, body=body, skip_auth=skip_auth, timeout=timeout)
  File "/home/main/tmp/ably-python-rest/ably/http/http.py", line 22, in wrapper
    return func(http, *args, **kwargs)
  File "/home/main/tmp/ably-python-rest/ably/http/http.py", line 46, in wrapper
    return func(rest, *args, **kwargs)
  File "/home/main/tmp/ably-python-rest/ably/http/http.py", line 160, in make_request
    AblyException.raise_for_response(response)
  File "/home/main/tmp/ably-python-rest/ably/util/exceptions.py", line 46, in raise_for_response
    response.status_code * 100)
AblyException: 
-------------------- >> begin captured logging << --------------------
ably.rest.auth: INFO: anonymous, using basic auth
ably.rest.auth: DEBUG: Auth callback: None
ably.rest.auth: DEBUG: Auth options: {'_AuthOptions__auth_url': None, '_Options__recover': False, '_Options__log_level': 0, '_AuthOptions__auth_params': None, '_Options__tls_port': 443, '_Options__host': 'staging-rest.ably.io', '_Options__client_id': None, '_AuthOptions__auth_headers': None, '_Options__port': 80, '_AuthOptions__query_time': False, '_AuthOptions__key_id': u'UFfQYg.UHfFcQ', '_AuthOptions__auth_callback': None, '_Options__ws_host': None, '_AuthOptions__key_value': u'Oicy4a7GJ43m_ZYq', '_AuthOptions__auth_token': None, '_Options__use_text_protocol': True, '_Options__tls': True, '_Options__queue_messages': False}
ably.rest.auth: DEBUG: Token Params: {'capability': <ably.types.capability.Capability object at 0x7f218ca31b50>, 'client_id': None}
ably.rest.auth: INFO: using token auth with client-side signing
ably.rest.auth: DEBUG: Key value: Oicy4a7GJ43m_ZYq
ably.rest.auth: DEBUG: Sign text: UFfQYg.UHfFcQ

{"onlythischannel": ["subscribe"]}

1427747774
6956503464018875

ably.rest.auth: INFO: generated signed request: {"nonce": "6956503464018875", "timestamp": 1427747774, "capability": "{\"onlythischannel\": [\"subscribe\"]}", "mac": "oZDOnO5aYUMOz08b80GsjJV3ZVfkYFpQmRUtgybR18c=", "client_id": "", "id": "UFfQYg.UHfFcQ"}
ably.util.exceptions: DEBUG: Response: 503 
--------------------- >> end captured logging << ---------------------

======================================================================
ERROR: test_request_token_with_duplicate_nonce (test.ably.resttoken_test.TestRestToken)
----------------------------------------------------------------------
Traceback (most recent call last):
  File "/home/main/tmp/ably-python-rest/test/ably/resttoken_test.py", line 89, in test_request_token_with_duplicate_nonce
    request_time = self.server_time()
  File "/home/main/tmp/ably-python-rest/test/ably/resttoken_test.py", line 23, in server_time
    return int(self.ably.time() / 1000.0)
  File "/home/main/tmp/ably-python-rest/ably/util/exceptions.py", line 61, in wrapper
    return func(*args, **kwargs)
  File "/home/main/tmp/ably-python-rest/ably/rest/rest.py", line 101, in time
    r = self.http.get('/time', skip_auth=True, timeout=timeout)
  File "/home/main/tmp/ably-python-rest/ably/http/http.py", line 168, in get
    return self.make_request('GET', url, headers=headers, skip_auth=skip_auth, timeout=timeout)
  File "/home/main/tmp/ably-python-rest/ably/http/http.py", line 22, in wrapper
    return func(http, *args, **kwargs)
  File "/home/main/tmp/ably-python-rest/ably/http/http.py", line 46, in wrapper
    return func(rest, *args, **kwargs)
  File "/home/main/tmp/ably-python-rest/ably/http/http.py", line 160, in make_request
    AblyException.raise_for_response(response)
  File "/home/main/tmp/ably-python-rest/ably/util/exceptions.py", line 46, in raise_for_response
    response.status_code * 100)
AblyException: 
-------------------- >> begin captured logging << --------------------
ably.rest.auth: INFO: anonymous, using basic auth
ably.util.exceptions: DEBUG: Response: 503 
--------------------- >> end captured logging << ---------------------

======================================================================
ERROR: test_request_token_with_specified_key (test.ably.resttoken_test.TestRestToken)
----------------------------------------------------------------------
Traceback (most recent call last):
  File "/home/main/tmp/ably-python-rest/test/ably/resttoken_test.py", line 121, in test_request_token_with_specified_key
    key_value=key["key_value"])
  File "/home/main/tmp/ably-python-rest/ably/rest/auth.py", line 145, in request_token
    skip_auth=True)
  File "/home/main/tmp/ably-python-rest/ably/http/http.py", line 171, in post
    return self.make_request('POST', url, headers=headers, body=body, skip_auth=skip_auth, timeout=timeout)
  File "/home/main/tmp/ably-python-rest/ably/http/http.py", line 22, in wrapper
    return func(http, *args, **kwargs)
  File "/home/main/tmp/ably-python-rest/ably/http/http.py", line 46, in wrapper
    return func(rest, *args, **kwargs)
  File "/home/main/tmp/ably-python-rest/ably/http/http.py", line 160, in make_request
    AblyException.raise_for_response(response)
  File "/home/main/tmp/ably-python-rest/ably/util/exceptions.py", line 46, in raise_for_response
    response.status_code * 100)
AblyException: 
-------------------- >> begin captured logging << --------------------
ably.rest.auth: INFO: anonymous, using basic auth
ably.rest.auth: DEBUG: Auth callback: None
ably.rest.auth: DEBUG: Auth options: {'_AuthOptions__auth_url': None, '_Options__recover': False, '_Options__log_level': 0, '_AuthOptions__auth_params': None, '_Options__tls_port': 443, '_Options__host': 'staging-rest.ably.io', '_Options__client_id': None, '_AuthOptions__auth_headers': None, '_Options__port': 80, '_AuthOptions__query_time': False, '_AuthOptions__key_id': u'UFfQYg.UHfFcQ', '_AuthOptions__auth_callback': None, '_Options__ws_host': None, '_AuthOptions__key_value': u'Oicy4a7GJ43m_ZYq', '_AuthOptions__auth_token': None, '_Options__use_text_protocol': True, '_Options__tls': True, '_Options__queue_messages': False}
ably.rest.auth: DEBUG: Token Params: {'client_id': None}
ably.rest.auth: INFO: using token auth with client-side signing
ably.rest.auth: DEBUG: Key value: F4-BVMwaIpHA3WAb
ably.rest.auth: DEBUG: Sign text: UFfQYg.yEpvUw



1427747776
9772379798448259

ably.rest.auth: INFO: generated signed request: {"nonce": "9772379798448259", "timestamp": 1427747776, "capability": "", "mac": "oVj0Wl/Se/2Vu4EJljb4Mb3Rt/0GsIDmgS6l24MdOhg=", "client_id": "", "id": "UFfQYg.yEpvUw"}
ably.util.exceptions: DEBUG: Response: 503 
--------------------- >> end captured logging << ---------------------

======================================================================
ERROR: test_request_token_with_specified_ttl (test.ably.resttoken_test.TestRestToken)
----------------------------------------------------------------------
Traceback (most recent call last):
  File "/home/main/tmp/ably-python-rest/test/ably/resttoken_test.py", line 133, in test_request_token_with_specified_ttl
    "ttl":100
  File "/home/main/tmp/ably-python-rest/ably/rest/auth.py", line 145, in request_token
    skip_auth=True)
  File "/home/main/tmp/ably-python-rest/ably/http/http.py", line 171, in post
    return self.make_request('POST', url, headers=headers, body=body, skip_auth=skip_auth, timeout=timeout)
  File "/home/main/tmp/ably-python-rest/ably/http/http.py", line 22, in wrapper
    return func(http, *args, **kwargs)
  File "/home/main/tmp/ably-python-rest/ably/http/http.py", line 46, in wrapper
    return func(rest, *args, **kwargs)
  File "/home/main/tmp/ably-python-rest/ably/http/http.py", line 160, in make_request
    AblyException.raise_for_response(response)
  File "/home/main/tmp/ably-python-rest/ably/util/exceptions.py", line 46, in raise_for_response
    response.status_code * 100)
AblyException: 
-------------------- >> begin captured logging << --------------------
ably.rest.auth: INFO: anonymous, using basic auth
ably.rest.auth: DEBUG: Auth callback: None
ably.rest.auth: DEBUG: Auth options: {'_AuthOptions__auth_url': None, '_Options__recover': False, '_Options__log_level': 0, '_AuthOptions__auth_params': None, '_Options__tls_port': 443, '_Options__host': 'staging-rest.ably.io', '_Options__client_id': None, '_AuthOptions__auth_headers': None, '_Options__port': 80, '_AuthOptions__query_time': False, '_AuthOptions__key_id': u'UFfQYg.UHfFcQ', '_AuthOptions__auth_callback': None, '_Options__ws_host': None, '_AuthOptions__key_value': u'Oicy4a7GJ43m_ZYq', '_AuthOptions__auth_token': None, '_Options__use_text_protocol': True, '_Options__tls': True, '_Options__queue_messages': False}
ably.rest.auth: DEBUG: Token Params: {'client_id': None, 'ttl': 100}
ably.rest.auth: INFO: using token auth with client-side signing
ably.rest.auth: DEBUG: Key value: Oicy4a7GJ43m_ZYq
ably.rest.auth: DEBUG: Sign text: UFfQYg.UHfFcQ
100


1427747776
8815301004927949

ably.rest.auth: INFO: generated signed request: {"nonce": "8815301004927949", "timestamp": 1427747776, "capability": "", "mac": "SWe1dtBZUrJkdh7SexmIzUVpN+SNKCyBM9PaJpC0lHY=", "client_id": "", "ttl": 100, "id": "UFfQYg.UHfFcQ"}
ably.util.exceptions: DEBUG: Response: 503 
--------------------- >> end captured logging << ---------------------

======================================================================
ERROR: test_request_token_with_system_timestamp (test.ably.resttoken_test.TestRestToken)
----------------------------------------------------------------------
Traceback (most recent call last):
  File "/home/main/tmp/ably-python-rest/test/ably/resttoken_test.py", line 74, in test_request_token_with_system_timestamp
    pre_time = self.server_time()
  File "/home/main/tmp/ably-python-rest/test/ably/resttoken_test.py", line 23, in server_time
    return int(self.ably.time() / 1000.0)
  File "/home/main/tmp/ably-python-rest/ably/util/exceptions.py", line 61, in wrapper
    return func(*args, **kwargs)
  File "/home/main/tmp/ably-python-rest/ably/rest/rest.py", line 101, in time
    r = self.http.get('/time', skip_auth=True, timeout=timeout)
  File "/home/main/tmp/ably-python-rest/ably/http/http.py", line 168, in get
    return self.make_request('GET', url, headers=headers, skip_auth=skip_auth, timeout=timeout)
  File "/home/main/tmp/ably-python-rest/ably/http/http.py", line 22, in wrapper
    return func(http, *args, **kwargs)
  File "/home/main/tmp/ably-python-rest/ably/http/http.py", line 46, in wrapper
    return func(rest, *args, **kwargs)
  File "/home/main/tmp/ably-python-rest/ably/http/http.py", line 160, in make_request
    AblyException.raise_for_response(response)
  File "/home/main/tmp/ably-python-rest/ably/util/exceptions.py", line 46, in raise_for_response
    response.status_code * 100)
AblyException: 
-------------------- >> begin captured logging << --------------------
ably.rest.auth: INFO: anonymous, using basic auth
ably.util.exceptions: DEBUG: Response: 503 
--------------------- >> end captured logging << ---------------------

======================================================================
ERROR: <nose.suite.ContextSuite context=test.ably>
test suite for <module 'test.ably' from '/home/main/tmp/ably-python-rest/test/ably/__init__.pyc'>
----------------------------------------------------------------------
Traceback (most recent call last):
  File "/home/main/.virtualenvs/ably/lib/python2.7/site-packages/nose/suite.py", line 228, in run
    self.tearDown()
  File "/home/main/.virtualenvs/ably/lib/python2.7/site-packages/nose/suite.py", line 351, in tearDown
    self.teardownContext(ancestor)
  File "/home/main/.virtualenvs/ably/lib/python2.7/site-packages/nose/suite.py", line 367, in teardownContext
    try_run(context, names)
  File "/home/main/.virtualenvs/ably/lib/python2.7/site-packages/nose/util.py", line 470, in try_run
    return func()
  File "/home/main/tmp/ably-python-rest/test/ably/__init__.py", line 7, in teardown_package
    RestSetup.clear_test_vars()
  File "/home/main/tmp/ably-python-rest/test/ably/restsetup.py", line 88, in clear_test_vars
    ably.http.delete('/apps/' + test_vars['app_id'], headers)
  File "/home/main/tmp/ably-python-rest/ably/http/http.py", line 174, in delete
    return self.make_request('DELETE', url, headers=headers, skip_auth=skip_auth, timeout=timeout)
  File "/home/main/tmp/ably-python-rest/ably/http/http.py", line 22, in wrapper
    return func(http, *args, **kwargs)
  File "/home/main/tmp/ably-python-rest/ably/http/http.py", line 51, in wrapper
    return func(rest, *args, **kwargs)
  File "/home/main/tmp/ably-python-rest/ably/http/http.py", line 160, in make_request
    AblyException.raise_for_response(response)
  File "/home/main/tmp/ably-python-rest/ably/util/exceptions.py", line 46, in raise_for_response
    response.status_code * 100)
AblyException: 
-------------------- >> begin captured logging << --------------------
ably.rest.auth: INFO: anonymous, using basic auth
ably.util.exceptions: DEBUG: Response: 503 
--------------------- >> end captured logging << ---------------------

======================================================================
FAIL: test_app_stats_01_minute_level_forwards (test.ably.restappstats_test.TestRestAppStats)
----------------------------------------------------------------------
Traceback (most recent call last):
  File "/home/main/tmp/ably-python-rest/test/ably/restappstats_test.py", line 95, in test_app_stats_01_minute_level_forwards
    self.assertEquals(1, len(stats_page), "Expected 1 record")
AssertionError: Expected 1 record
-------------------- >> begin captured logging << --------------------
ably.rest.auth: INFO: no authentication parameters supplied
test.ably.restsetup: DEBUG: [(u'UFfQYg', u'UHfFcQ', u'Oicy4a7GJ43m_ZYq'), (u'UFfQYg', u'yEpvUw', u'F4-BVMwaIpHA3WAb'), (u'UFfQYg', u'y7r78Q', u'Pv74O5woyNr_Cv-X'), (u'UFfQYg', u'CORnJQ', u'XZ5knxLdupQsd3WB'), (u'UFfQYg', u'D2TV8A', u'91AVBpZblUqye1X_'), (u'UFfQYg', u'PbA8GA', u'zG6ZLwW4fZZnO0LX')]
test.ably.restappstats_test: DEBUG: KEY init: UFfQYg.UHfFcQ:Oicy4a7GJ43m_ZYq
test.ably.restappstats_test: DEBUG: KEY class: UFfQYg.UHfFcQ:Oicy4a7GJ43m_ZYq
test.ably.restappstats_test: DEBUG: TLS: True
ably.rest.auth: INFO: anonymous, using basic auth
ably.http.paginatedresult: DEBUG: Links: {'current': {'url': './stats?start=1427729520000&end=1427729525000&limit=100&unit=minute&direction=forwards&format=json&first_start=1427729520000', 'rel': 'current'}, 'first': {'url': './stats?start=1427729520000&end=1427729525000&limit=100&unit=minute&direction=forwards&format=json&first_start=1427729520000', 'rel': 'first'}}
ably.http.paginatedresult: DEBUG: Response: <ably.http.http.Response object at 0x7f218d12cf50>
--------------------- >> end captured logging << ---------------------

======================================================================
FAIL: test_app_stats_02_hour_level_forwards (test.ably.restappstats_test.TestRestAppStats)
----------------------------------------------------------------------
Traceback (most recent call last):
  File "/home/main/tmp/ably-python-rest/test/ably/restappstats_test.py", line 108, in test_app_stats_02_hour_level_forwards
    self.assertEquals(1, len(stats_page), "Expected 1 record")
AssertionError: Expected 1 record
-------------------- >> begin captured logging << --------------------
ably.http.paginatedresult: DEBUG: Links: {'current': {'url': './stats?start=1427727600000&end=1427729525000&limit=100&unit=hour&direction=forwards&format=json&first_start=1427727600000', 'rel': 'current'}, 'first': {'url': './stats?start=1427727600000&end=1427729525000&limit=100&unit=hour&direction=forwards&format=json&first_start=1427727600000', 'rel': 'first'}}
ably.http.paginatedresult: DEBUG: Response: <ably.http.http.Response object at 0x7f218d12ca50>
--------------------- >> end captured logging << ---------------------

======================================================================
FAIL: test_app_stats_05_minute_level_backwards (test.ably.restappstats_test.TestRestAppStats)
----------------------------------------------------------------------
Traceback (most recent call last):
  File "/home/main/tmp/ably-python-rest/test/ably/restappstats_test.py", line 147, in test_app_stats_05_minute_level_backwards
    self.assertEquals(1, len(stats_page), "Expected 1 record")
AssertionError: Expected 1 record
-------------------- >> begin captured logging << --------------------
ably.http.paginatedresult: DEBUG: Links: {'current': {'url': './stats?start=1427729580000&end=1427729586000&limit=100&unit=minute&direction=backwards&format=json&first_end=1427729586000', 'rel': 'current'}, 'first': {'url': './stats?start=1427729580000&end=1427729586000&limit=100&unit=minute&direction=backwards&format=json&first_end=1427729586000', 'rel': 'first'}}
ably.http.paginatedresult: DEBUG: Response: <ably.http.http.Response object at 0x7f218d159fd0>
--------------------- >> end captured logging << ---------------------

======================================================================
FAIL: test_app_stats_06_hour_level_backwards (test.ably.restappstats_test.TestRestAppStats)
----------------------------------------------------------------------
Traceback (most recent call last):
  File "/home/main/tmp/ably-python-rest/test/ably/restappstats_test.py", line 160, in test_app_stats_06_hour_level_backwards
    self.assertTrue(1 == len(stats_page) or 2 == len(stats_page), "Expected 1 or 2 records")
AssertionError: Expected 1 or 2 records
-------------------- >> begin captured logging << --------------------
ably.http.paginatedresult: DEBUG: Links: {'current': {'url': './stats?start=1427727600000&end=1427729586000&limit=100&unit=hour&direction=backwards&format=json&first_end=1427729586000', 'rel': 'current'}, 'first': {'url': './stats?start=1427727600000&end=1427729586000&limit=100&unit=hour&direction=backwards&format=json&first_end=1427729586000', 'rel': 'first'}}
ably.http.paginatedresult: DEBUG: Response: <ably.http.http.Response object at 0x7f218d159c10>
--------------------- >> end captured logging << ---------------------

======================================================================
FAIL: test_app_stats_09_limit_backwards (test.ably.restappstats_test.TestRestAppStats)
----------------------------------------------------------------------
Traceback (most recent call last):
  File "/home/main/tmp/ably-python-rest/test/ably/restappstats_test.py", line 210, in test_app_stats_09_limit_backwards
    self.assertEquals(1, len(stats_page), "Expected 1 record")
AssertionError: Expected 1 record
-------------------- >> begin captured logging << --------------------
ably.http.paginatedresult: DEBUG: Links: {'current': {'url': './stats?start=1427729520000&end=1427729646000&limit=1&unit=minute&direction=backwards&format=json&first_end=1427729646000', 'rel': 'current'}, 'first': {'url': './stats?start=1427729520000&end=1427729646000&limit=1&unit=minute&direction=backwards&format=json&first_end=1427729646000', 'rel': 'first'}}
ably.http.paginatedresult: DEBUG: Response: <ably.http.http.Response object at 0x7f218caca510>
--------------------- >> end captured logging << ---------------------

======================================================================
FAIL: test_app_stats_10_limit_forwards (test.ably.restappstats_test.TestRestAppStats)
----------------------------------------------------------------------
Traceback (most recent call last):
  File "/home/main/tmp/ably-python-rest/test/ably/restappstats_test.py", line 223, in test_app_stats_10_limit_forwards
    self.assertEquals(1, len(stats_page), "Expected 1 record")
AssertionError: Expected 1 record
-------------------- >> begin captured logging << --------------------
ably.http.paginatedresult: DEBUG: Links: {'current': {'url': './stats?start=1427729520000&end=1427729646000&limit=1&unit=minute&direction=forwards&format=json&first_start=1427729520000', 'rel': 'current'}, 'first': {'url': './stats?start=1427729520000&end=1427729646000&limit=1&unit=minute&direction=forwards&format=json&first_start=1427729520000', 'rel': 'first'}}
ably.http.paginatedresult: DEBUG: Response: <ably.http.http.Response object at 0x7f218caca310>
--------------------- >> end captured logging << ---------------------

======================================================================
FAIL: test_app_stats_11_pagination_backwards (test.ably.restappstats_test.TestRestAppStats)
----------------------------------------------------------------------
Traceback (most recent call last):
  File "/home/main/tmp/ably-python-rest/test/ably/restappstats_test.py", line 236, in test_app_stats_11_pagination_backwards
    self.assertEquals(1, len(stats_page), "Expected 1 record")
AssertionError: Expected 1 record
-------------------- >> begin captured logging << --------------------
ably.http.paginatedresult: DEBUG: Links: {'current': {'url': './stats?start=1427729520000&end=1427729646000&limit=1&unit=minute&direction=backwards&format=json&first_end=1427729646000', 'rel': 'current'}, 'first': {'url': './stats?start=1427729520000&end=1427729646000&limit=1&unit=minute&direction=backwards&format=json&first_end=1427729646000', 'rel': 'first'}}
ably.http.paginatedresult: DEBUG: Response: <ably.http.http.Response object at 0x7f218caca390>
--------------------- >> end captured logging << ---------------------

======================================================================
FAIL: test_app_stats_12_pagination_forwards (test.ably.restappstats_test.TestRestAppStats)
----------------------------------------------------------------------
Traceback (most recent call last):
  File "/home/main/tmp/ably-python-rest/test/ably/restappstats_test.py", line 267, in test_app_stats_12_pagination_forwards
    self.assertEquals(1, len(stats_page), "Expected 1 record")
AssertionError: Expected 1 record
-------------------- >> begin captured logging << --------------------
ably.http.paginatedresult: DEBUG: Links: {'current': {'url': './stats?start=1427729520000&end=1427729646000&limit=1&unit=minute&direction=forwards&format=json&first_start=1427729520000', 'rel': 'current'}, 'first': {'url': './stats?start=1427729520000&end=1427729646000&limit=1&unit=minute&direction=forwards&format=json&first_start=1427729520000', 'rel': 'first'}}
ably.http.paginatedresult: DEBUG: Response: <ably.http.http.Response object at 0x7f218cacab10>
--------------------- >> end captured logging << ---------------------

======================================================================
FAIL: test_app_stats_13_pagination_backwards_get_first (test.ably.restappstats_test.TestRestAppStats)
----------------------------------------------------------------------
Traceback (most recent call last):
  File "/home/main/tmp/ably-python-rest/test/ably/restappstats_test.py", line 298, in test_app_stats_13_pagination_backwards_get_first
    self.assertEquals(1, len(stats_page), "Expected 1 record")
AssertionError: Expected 1 record
-------------------- >> begin captured logging << --------------------
ably.http.paginatedresult: DEBUG: Links: {'current': {'url': './stats?start=1427729520000&end=1427729646000&limit=1&unit=minute&direction=backwards&format=json&first_end=1427729646000', 'rel': 'current'}, 'first': {'url': './stats?start=1427729520000&end=1427729646000&limit=1&unit=minute&direction=backwards&format=json&first_end=1427729646000', 'rel': 'first'}}
ably.http.paginatedresult: DEBUG: Response: <ably.http.http.Response object at 0x7f218cacaa90>
--------------------- >> end captured logging << ---------------------

======================================================================
FAIL: test_app_stats_14_pagination_forwards_get_first (test.ably.restappstats_test.TestRestAppStats)
----------------------------------------------------------------------
Traceback (most recent call last):
  File "/home/main/tmp/ably-python-rest/test/ably/restappstats_test.py", line 325, in test_app_stats_14_pagination_forwards_get_first
    self.assertEquals(1, len(stats_page), "Expected 1 record")
AssertionError: Expected 1 record
-------------------- >> begin captured logging << --------------------
ably.http.paginatedresult: DEBUG: Links: {'current': {'url': './stats?start=1427729520000&end=1427729646000&limit=1&unit=minute&direction=forwards&format=json&first_start=1427729520000', 'rel': 'current'}, 'first': {'url': './stats?start=1427729520000&end=1427729646000&limit=1&unit=minute&direction=forwards&format=json&first_start=1427729520000', 'rel': 'first'}}
ably.http.paginatedresult: DEBUG: Response: <ably.http.http.Response object at 0x7f218caca910>
--------------------- >> end captured logging << ---------------------

----------------------------------------------------------------------
Ran 70 tests in 282.727s

FAILED (failures=10, errors=23)
